// Handling errors with try-catch blocks
try {
    const pi = 3.14;

pi = 5; // typeError
}
catch(err) {
    console.log('We got an error!');
}

for(let i = 5; i <= 10; i ++) {
    console.log(i);
}